<?xml version='1.0' encoding='utf-8'?>
<mujoco model="bjj_scene"><compiler angle="radian" coordinate="local" /><option timestep="0.00005" gravity="0 0 -9.81" /><visual><rgba haze="0.15 0.25 0.35 1" /></visual><default><joint armature="0.01" damping="0.1" limited="true" /><geom contype="1" conaffinity="1" friction="1 0.5 0.5" margin="0.001" /></default><asset><material name="red" rgba="0.8 0.2 0.2 1" /><material name="blue" rgba="0.2 0.2 0.8 1" /><material name="mat_ground" rgba="0.5 0.5 0.5 1" /></asset><worldbody><light directional="true" pos="0 0 3" dir="0 0 -1" /><geom name="ground" type="plane" pos="0 0 -0.6176" size="5 5 0.1" material="mat_ground" condim="3" /><body name="player1_Core" pos="2.4768 -2.1348 0.6780"><geom type="sphere" size="0.1" material="red" /><freejoint name="player1_root" /><geom type="capsule" fromto="0 0 0 -0.0360 -0.1464 -0.2868" size="0.0900" material="red" /><body name="player1_LeftHip" pos="-0.0360 -0.1464 -0.2868"><geom type="sphere" size="0.09" material="red" /><joint name="player1_LeftHip_joint" type="ball" limited="false" damping="0.5" /><geom type="capsule" fromto="0 0 0 -0.3384 -0.1572 -0.3768" size="0.0500" material="red" /><body name="player1_LeftKnee" pos="-0.3384 -0.1572 -0.3768"><geom type="sphere" size="0.05" material="red" /><joint name="player1_LeftKnee_joint" type="hinge" axis="0 1 0" limited="true" range="-2.3 0" damping="0.5" /><geom type="capsule" fromto="0 0 0 0.0852 -0.0456 -0.4980" size="0.0300" material="red" /><body name="player1_LeftAnkle" pos="0.0852 -0.0456 -0.4980"><geom type="sphere" size="0.03" material="red" /><joint name="player1_LeftAnkle_joint" type="hinge" axis="1 0 0" limited="false" damping="0.5" /><geom type="capsule" fromto="0 0 0 0.0720 0.0180 -0.0804" size="0.0300" material="red" /><body name="player1_LeftHeel" pos="0.0720 0.0180 -0.0804"><geom type="sphere" size="0.03" material="red" /><joint name="player1_LeftHeel_joint" type="hinge" axis="1 0 0" limited="false" damping="0.5" /><geom type="capsule" fromto="0 0 0 -0.2520 -0.1092 -0.0024" size="0.0250" material="red" /><body name="player1_LeftToe" pos="-0.2520 -0.1092 -0.0024"><geom type="sphere" size="0.025" material="red" /><joint name="player1_LeftToe_joint" type="hinge" axis="1 0 0" limited="false" damping="0.5" /></body></body></body></body></body><geom type="capsule" fromto="0 0 0 0.0480 0.1188 -0.3012" size="0.0900" material="red" /><body name="player1_RightHip" pos="0.0480 0.1188 -0.3012"><geom type="sphere" size="0.09" material="red" /><joint name="player1_RightHip_joint" type="ball" limited="false" damping="0.5" /><geom type="capsule" fromto="0 0 0 0.1116 0.1320 -0.5016" size="0.0500" material="red" /><body name="player1_RightKnee" pos="0.1116 0.1320 -0.5016"><geom type="sphere" size="0.05" material="red" /><joint name="player1_RightKnee_joint" type="hinge" axis="0 1 0" limited="true" range="-2.3 0" damping="0.5" /><geom type="capsule" fromto="0 0 0 0.3624 0.0216 -0.3540" size="0.0300" material="red" /><body name="player1_RightAnkle" pos="0.3624 0.0216 -0.3540"><geom type="sphere" size="0.03" material="red" /><joint name="player1_RightAnkle_joint" type="hinge" axis="1 0 0" limited="false" damping="0.5" /><geom type="capsule" fromto="0 0 0 0.0708 -0.0012 -0.0852" size="0.0300" material="red" /><body name="player1_RightHeel" pos="0.0708 -0.0012 -0.0852"><geom type="sphere" size="0.03" material="red" /><joint name="player1_RightHeel_joint" type="hinge" axis="1 0 0" limited="false" damping="0.5" /><geom type="capsule" fromto="0 0 0 -0.2568 0.0924 0.0144" size="0.0250" material="red" /><body name="player1_RightToe" pos="-0.2568 0.0924 0.0144"><geom type="sphere" size="0.025" material="red" /><joint name="player1_RightToe_joint" type="hinge" axis="1 0 0" limited="false" damping="0.5" /></body></body></body></body></body><geom type="capsule" fromto="0 0 0 -0.2616 -0.0588 0.4008" size="0.0500" material="red" /><body name="player1_Neck" pos="-0.2616 -0.0588 0.4008"><geom type="sphere" size="0.05" material="red" /><joint name="player1_Neck_joint" type="hinge" axis="1 0 0" limited="false" damping="0.5" /><geom type="capsule" fromto="0 0 0 -0.1644 -0.0120 0.1152" size="0.0500" material="red" /><body name="player1_Head" pos="-0.1644 -0.0120 0.1152"><geom type="sphere" size="0.11" material="red" /><joint name="player1_Head_joint" type="hinge" axis="1 0 0" limited="false" damping="0.5" /></body><geom type="capsule" fromto="0 0 0 0.0384 -0.1836 -0.0996" size="0.0500" material="red" /><body name="player1_LeftShoulder" pos="0.0384 -0.1836 -0.0996"><geom type="sphere" size="0.08" material="red" /><joint name="player1_LeftShoulder_joint" type="ball" limited="false" damping="0.5" /><geom type="capsule" fromto="0 0 0 -0.1836 -0.2184 -0.2052" size="0.0450" material="red" /><body name="player1_LeftElbow" pos="-0.1836 -0.2184 -0.2052"><geom type="sphere" size="0.045" material="red" /><joint name="player1_LeftElbow_joint" type="hinge" axis="0 1 0" limited="true" range="-2.3 0" damping="0.5" /><geom type="capsule" fromto="0 0 0 -0.2808 -0.0024 0.1404" size="0.0200" material="red" /><body name="player1_LeftWrist" pos="-0.2808 -0.0024 0.1404"><geom type="sphere" size="0.02" material="red" /><joint name="player1_LeftWrist_joint" type="hinge" axis="1 0 0" limited="false" damping="0.5" /><geom type="capsule" fromto="0 0 0 -0.0552 -0.0468 0.0660" size="0.0200" material="red" /><body name="player1_LeftHand" pos="-0.0552 -0.0468 0.0660"><geom type="sphere" size="0.02" material="red" /><joint name="player1_LeftHand_joint" type="hinge" axis="1 0 0" limited="false" damping="0.5" /><geom type="capsule" fromto="0 0 0 -0.0936 0.0228 0.0108" size="0.0200" material="red" /><body name="player1_LeftFingers" pos="-0.0936 0.0228 0.0108"><geom type="sphere" size="0.02" material="red" /><joint name="player1_LeftFingers_joint" type="hinge" axis="1 0 0" limited="false" damping="0.5" /></body></body></body></body></body><geom type="capsule" fromto="0 0 0 0.0312 0.2052 -0.0480" size="0.0500" material="red" /><body name="player1_RightShoulder" pos="0.0312 0.2052 -0.0480"><geom type="sphere" size="0.08" material="red" /><joint name="player1_RightShoulder_joint" type="ball" limited="false" damping="0.5" /><geom type="capsule" fromto="0 0 0 -0.2424 -0.0360 -0.2496" size="0.0450" material="red" /><body name="player1_RightElbow" pos="-0.2424 -0.0360 -0.2496"><geom type="sphere" size="0.045" material="red" /><joint name="player1_RightElbow_joint" type="hinge" axis="0 1 0" limited="true" range="-2.3 0" damping="0.5" /><geom type="capsule" fromto="0 0 0 -0.2604 -0.0744 0.1800" size="0.0200" material="red" /><body name="player1_RightWrist" pos="-0.2604 -0.0744 0.1800"><geom type="sphere" size="0.02" material="red" /><joint name="player1_RightWrist_joint" type="hinge" axis="1 0 0" limited="false" damping="0.5" /><geom type="capsule" fromto="0 0 0 -0.0720 -0.0180 0.0588" size="0.0200" material="red" /><body name="player1_RightHand" pos="-0.0720 -0.0180 0.0588"><geom type="sphere" size="0.02" material="red" /><joint name="player1_RightHand_joint" type="hinge" axis="1 0 0" limited="false" damping="0.5" /><geom type="capsule" fromto="0 0 0 -0.0864 -0.0324 -0.0204" size="0.0200" material="red" /><body name="player1_RightFingers" pos="-0.0864 -0.0324 -0.0204"><geom type="sphere" size="0.02" material="red" /><joint name="player1_RightFingers_joint" type="hinge" axis="1 0 0" limited="false" damping="0.5" /></body></body></body></body></body></body></body><body name="player2_Core" pos="0.8700 -2.4684 0.6780"><geom type="sphere" size="0.1" material="blue" /><freejoint name="player2_root" /><geom type="capsule" fromto="0 0 0 -0.0936 0.0888 -0.2928" size="0.0900" material="blue" /><body name="player2_LeftHip" pos="-0.0936 0.0888 -0.2928"><geom type="sphere" size="0.09" material="blue" /><joint name="player2_LeftHip_joint" type="ball" limited="false" damping="0.5" /><geom type="capsule" fromto="0 0 0 -0.0576 0.1260 -0.5076" size="0.0500" material="blue" /><body name="player2_LeftKnee" pos="-0.0576 0.1260 -0.5076"><geom type="sphere" size="0.05" material="blue" /><joint name="player2_LeftKnee_joint" type="hinge" axis="0 1 0" limited="true" range="-2.3 0" damping="0.5" /><geom type="capsule" fromto="0 0 0 -0.3432 -0.1224 -0.3456" size="0.0300" material="blue" /><body name="player2_LeftAnkle" pos="-0.3432 -0.1224 -0.3456"><geom type="sphere" size="0.03" material="blue" /><joint name="player2_LeftAnkle_joint" type="hinge" axis="1 0 0" limited="false" damping="0.5" /><geom type="capsule" fromto="0 0 0 -0.0756 -0.0348 -0.0648" size="0.0300" material="blue" /><body name="player2_LeftHeel" pos="-0.0756 -0.0348 -0.0648"><geom type="sphere" size="0.03" material="blue" /><joint name="player2_LeftHeel_joint" type="hinge" axis="1 0 0" limited="false" damping="0.5" /><geom type="capsule" fromto="0 0 0 0.2352 0.1428 -0.0348" size="0.0250" material="blue" /><body name="player2_LeftToe" pos="0.2352 0.1428 -0.0348"><geom type="sphere" size="0.025" material="blue" /><joint name="player2_LeftToe_joint" type="hinge" axis="1 0 0" limited="false" damping="0.5" /></body></body></body></body></body><geom type="capsule" fromto="0 0 0 0.0732 -0.1332 -0.2832" size="0.0900" material="blue" /><body name="player2_RightHip" pos="0.0732 -0.1332 -0.2832"><geom type="sphere" size="0.09" material="blue" /><joint name="player2_RightHip_joint" type="ball" limited="false" damping="0.5" /><geom type="capsule" fromto="0 0 0 0.3720 -0.0360 -0.3696" size="0.0500" material="blue" /><body name="player2_RightKnee" pos="0.3720 -0.0360 -0.3696"><geom type="sphere" size="0.05" material="blue" /><joint name="player2_RightKnee_joint" type="hinge" axis="0 1 0" limited="true" range="-2.3 0" damping="0.5" /><geom type="capsule" fromto="0 0 0 -0.0480 -0.0612 -0.4992" size="0.0300" material="blue" /><body name="player2_RightAnkle" pos="-0.0480 -0.0612 -0.4992"><geom type="sphere" size="0.03" material="blue" /><joint name="player2_RightAnkle_joint" type="hinge" axis="1 0 0" limited="false" damping="0.5" /><geom type="capsule" fromto="0 0 0 -0.0744 -0.0132 -0.0804" size="0.0300" material="blue" /><body name="player2_RightHeel" pos="-0.0744 -0.0132 -0.0804"><geom type="sphere" size="0.03" material="blue" /><joint name="player2_RightHeel_joint" type="hinge" axis="1 0 0" limited="false" damping="0.5" /><geom type="capsule" fromto="0 0 0 0.2724 0.0132 -0.0120" size="0.0250" material="blue" /><body name="player2_RightToe" pos="0.2724 0.0132 -0.0120"><geom type="sphere" size="0.025" material="blue" /><joint name="player2_RightToe_joint" type="hinge" axis="1 0 0" limited="false" damping="0.5" /></body></body></body></body></body><geom type="capsule" fromto="0 0 0 0.2436 0.0192 0.4176" size="0.0500" material="blue" /><body name="player2_Neck" pos="0.2436 0.0192 0.4176"><geom type="sphere" size="0.05" material="blue" /><joint name="player2_Neck_joint" type="hinge" axis="1 0 0" limited="false" damping="0.5" /><geom type="capsule" fromto="0 0 0 0.1560 0.0300 0.1176" size="0.0500" material="blue" /><body name="player2_Head" pos="0.1560 0.0300 0.1176"><geom type="sphere" size="0.11" material="blue" /><joint name="player2_Head_joint" type="hinge" axis="1 0 0" limited="false" damping="0.5" /></body><geom type="capsule" fromto="0 0 0 -0.0600 0.1860 -0.0696" size="0.0500" material="blue" /><body name="player2_LeftShoulder" pos="-0.0600 0.1860 -0.0696"><geom type="sphere" size="0.08" material="blue" /><joint name="player2_LeftShoulder_joint" type="ball" limited="false" damping="0.5" /><geom type="capsule" fromto="0 0 0 0.2136 0.1356 -0.2364" size="0.0450" material="blue" /><body name="player2_LeftElbow" pos="0.2136 0.1356 -0.2364"><geom type="sphere" size="0.045" material="blue" /><joint name="player2_LeftElbow_joint" type="hinge" axis="0 1 0" limited="true" range="-2.3 0" damping="0.5" /><geom type="capsule" fromto="0 0 0 0.2616 0.0612 0.1548" size="0.0200" material="blue" /><body name="player2_LeftWrist" pos="0.2616 0.0612 0.1548"><geom type="sphere" size="0.02" material="blue" /><joint name="player2_LeftWrist_joint" type="hinge" axis="1 0 0" limited="false" damping="0.5" /><geom type="capsule" fromto="0 0 0 0.0444 0.0048 0.0852" size="0.0200" material="blue" /><body name="player2_LeftHand" pos="0.0444 0.0048 0.0852"><geom type="sphere" size="0.02" material="blue" /><joint name="player2_LeftHand_joint" type="hinge" axis="1 0 0" limited="false" damping="0.5" /><geom type="capsule" fromto="0 0 0 0.0984 0.0084 -0.0048" size="0.0200" material="blue" /><body name="player2_LeftFingers" pos="0.0984 0.0084 -0.0048"><geom type="sphere" size="0.02" material="blue" /><joint name="player2_LeftFingers_joint" type="hinge" axis="1 0 0" limited="false" damping="0.5" /></body></body></body></body></body><geom type="capsule" fromto="0 0 0 -0.0216 -0.1956 -0.0732" size="0.0500" material="blue" /><body name="player2_RightShoulder" pos="-0.0216 -0.1956 -0.0732"><geom type="sphere" size="0.08" material="blue" /><joint name="player2_RightShoulder_joint" type="ball" limited="false" damping="0.5" /><geom type="capsule" fromto="0 0 0 0.2772 -0.0336 -0.2040" size="0.0450" material="blue" /><body name="player2_RightElbow" pos="0.2772 -0.0336 -0.2040"><geom type="sphere" size="0.045" material="blue" /><joint name="player2_RightElbow_joint" type="hinge" axis="0 1 0" limited="true" range="-2.3 0" damping="0.5" /><geom type="capsule" fromto="0 0 0 0.2844 0.0732 0.1320" size="0.0200" material="blue" /><body name="player2_RightWrist" pos="0.2844 0.0732 0.1320"><geom type="sphere" size="0.02" material="blue" /><joint name="player2_RightWrist_joint" type="hinge" axis="1 0 0" limited="false" damping="0.5" /><geom type="capsule" fromto="0 0 0 0.0576 0.0384 0.0672" size="0.0200" material="blue" /><body name="player2_RightHand" pos="0.0576 0.0384 0.0672"><geom type="sphere" size="0.02" material="blue" /><joint name="player2_RightHand_joint" type="hinge" axis="1 0 0" limited="false" damping="0.5" /><geom type="capsule" fromto="0 0 0 0.0960 0.0168 -0.0180" size="0.0200" material="blue" /><body name="player2_RightFingers" pos="0.0960 0.0168 -0.0180"><geom type="sphere" size="0.02" material="blue" /><joint name="player2_RightFingers_joint" type="hinge" axis="1 0 0" limited="false" damping="0.5" /></body></body></body></body></body></body></body></worldbody><actuator><position name="player1_LeftHip_joint_act" joint="player1_LeftHip_joint" kp="50" /><position name="player1_LeftKnee_joint_act" joint="player1_LeftKnee_joint" kp="50" /><position name="player1_LeftAnkle_joint_act" joint="player1_LeftAnkle_joint" kp="50" /><position name="player1_LeftHeel_joint_act" joint="player1_LeftHeel_joint" kp="50" /><position name="player1_LeftToe_joint_act" joint="player1_LeftToe_joint" kp="50" /><position name="player1_RightHip_joint_act" joint="player1_RightHip_joint" kp="50" /><position name="player1_RightKnee_joint_act" joint="player1_RightKnee_joint" kp="50" /><position name="player1_RightAnkle_joint_act" joint="player1_RightAnkle_joint" kp="50" /><position name="player1_RightHeel_joint_act" joint="player1_RightHeel_joint" kp="50" /><position name="player1_RightToe_joint_act" joint="player1_RightToe_joint" kp="50" /><position name="player1_Neck_joint_act" joint="player1_Neck_joint" kp="50" /><position name="player1_Head_joint_act" joint="player1_Head_joint" kp="50" /><position name="player1_LeftShoulder_joint_act" joint="player1_LeftShoulder_joint" kp="50" /><position name="player1_LeftElbow_joint_act" joint="player1_LeftElbow_joint" kp="50" /><position name="player1_LeftWrist_joint_act" joint="player1_LeftWrist_joint" kp="50" /><position name="player1_LeftHand_joint_act" joint="player1_LeftHand_joint" kp="50" /><position name="player1_LeftFingers_joint_act" joint="player1_LeftFingers_joint" kp="50" /><position name="player1_RightShoulder_joint_act" joint="player1_RightShoulder_joint" kp="50" /><position name="player1_RightElbow_joint_act" joint="player1_RightElbow_joint" kp="50" /><position name="player1_RightWrist_joint_act" joint="player1_RightWrist_joint" kp="50" /><position name="player1_RightHand_joint_act" joint="player1_RightHand_joint" kp="50" /><position name="player1_RightFingers_joint_act" joint="player1_RightFingers_joint" kp="50" /><position name="player2_LeftHip_joint_act" joint="player2_LeftHip_joint" kp="50" /><position name="player2_LeftKnee_joint_act" joint="player2_LeftKnee_joint" kp="50" /><position name="player2_LeftAnkle_joint_act" joint="player2_LeftAnkle_joint" kp="50" /><position name="player2_LeftHeel_joint_act" joint="player2_LeftHeel_joint" kp="50" /><position name="player2_LeftToe_joint_act" joint="player2_LeftToe_joint" kp="50" /><position name="player2_RightHip_joint_act" joint="player2_RightHip_joint" kp="50" /><position name="player2_RightKnee_joint_act" joint="player2_RightKnee_joint" kp="50" /><position name="player2_RightAnkle_joint_act" joint="player2_RightAnkle_joint" kp="50" /><position name="player2_RightHeel_joint_act" joint="player2_RightHeel_joint" kp="50" /><position name="player2_RightToe_joint_act" joint="player2_RightToe_joint" kp="50" /><position name="player2_Neck_joint_act" joint="player2_Neck_joint" kp="50" /><position name="player2_Head_joint_act" joint="player2_Head_joint" kp="50" /><position name="player2_LeftShoulder_joint_act" joint="player2_LeftShoulder_joint" kp="50" /><position name="player2_LeftElbow_joint_act" joint="player2_LeftElbow_joint" kp="50" /><position name="player2_LeftWrist_joint_act" joint="player2_LeftWrist_joint" kp="50" /><position name="player2_LeftHand_joint_act" joint="player2_LeftHand_joint" kp="50" /><position name="player2_LeftFingers_joint_act" joint="player2_LeftFingers_joint" kp="50" /><position name="player2_RightShoulder_joint_act" joint="player2_RightShoulder_joint" kp="50" /><position name="player2_RightElbow_joint_act" joint="player2_RightElbow_joint" kp="50" /><position name="player2_RightWrist_joint_act" joint="player2_RightWrist_joint" kp="50" /><position name="player2_RightHand_joint_act" joint="player2_RightHand_joint" kp="50" /><position name="player2_RightFingers_joint_act" joint="player2_RightFingers_joint" kp="50" /></actuator></mujoco>