<?xml version='1.0' encoding='utf-8'?>
<mujoco model="bjj_player1"><compiler angle="radian" coordinate="local" /><default><joint armature="0.01" damping="0.1" limited="true" /><geom contype="1" conaffinity="1" friction="1 0.5 0.5" /></default><asset><material name="red" rgba="0.8 0.2 0.2 1" /></asset><worldbody><geom name="floor" type="plane" pos="0 0 -0.6176" size="30 30 0.1" rgba="0.8 0.8 0.8 1" /><body name="player1_Core" pos="2.4768 -2.1348 0.6780"><geom type="sphere" size="0.1" material="red" /><freejoint name="player1_root" /><geom type="capsule" fromto="0 0 0 -0.0360 -0.1464 -0.2868" size="0.0900" material="red" /><body name="player1_LeftHip" pos="-0.0360 -0.1464 -0.2868"><geom type="sphere" size="0.09" material="red" /><joint name="player1_LeftHip_joint" type="ball" limited="false" damping="0.5" /><geom type="capsule" fromto="0 0 0 -0.3384 -0.1572 -0.3768" size="0.0500" material="red" /><body name="player1_LeftKnee" pos="-0.3384 -0.1572 -0.3768"><geom type="sphere" size="0.05" material="red" /><joint name="player1_LeftKnee_joint" type="hinge" axis="0 1 0" limited="true" range="-2.3 0" damping="0.5" /><geom type="capsule" fromto="0 0 0 0.0852 -0.0456 -0.4980" size="0.0300" material="red" /><body name="player1_LeftAnkle" pos="0.0852 -0.0456 -0.4980"><geom type="sphere" size="0.03" material="red" /><joint name="player1_LeftAnkle_joint" type="hinge" axis="1 0 0" limited="false" damping="0.5" /><geom type="capsule" fromto="0 0 0 0.0720 0.0180 -0.0804" size="0.0300" material="red" /><body name="player1_LeftHeel" pos="0.0720 0.0180 -0.0804"><geom type="sphere" size="0.03" material="red" /><joint name="player1_LeftHeel_joint" type="hinge" axis="1 0 0" limited="false" damping="0.5" /><geom type="capsule" fromto="0 0 0 -0.2520 -0.1092 -0.0024" size="0.0250" material="red" /><body name="player1_LeftToe" pos="-0.2520 -0.1092 -0.0024"><geom type="sphere" size="0.025" material="red" /><joint name="player1_LeftToe_joint" type="hinge" axis="1 0 0" limited="false" damping="0.5" /></body></body></body></body></body><geom type="capsule" fromto="0 0 0 0.0480 0.1188 -0.3012" size="0.0900" material="red" /><body name="player1_RightHip" pos="0.0480 0.1188 -0.3012"><geom type="sphere" size="0.09" material="red" /><joint name="player1_RightHip_joint" type="ball" limited="false" damping="0.5" /><geom type="capsule" fromto="0 0 0 0.1116 0.1320 -0.5016" size="0.0500" material="red" /><body name="player1_RightKnee" pos="0.1116 0.1320 -0.5016"><geom type="sphere" size="0.05" material="red" /><joint name="player1_RightKnee_joint" type="hinge" axis="0 1 0" limited="true" range="-2.3 0" damping="0.5" /><geom type="capsule" fromto="0 0 0 0.3624 0.0216 -0.3540" size="0.0300" material="red" /><body name="player1_RightAnkle" pos="0.3624 0.0216 -0.3540"><geom type="sphere" size="0.03" material="red" /><joint name="player1_RightAnkle_joint" type="hinge" axis="1 0 0" limited="false" damping="0.5" /><geom type="capsule" fromto="0 0 0 0.0708 -0.0012 -0.0852" size="0.0300" material="red" /><body name="player1_RightHeel" pos="0.0708 -0.0012 -0.0852"><geom type="sphere" size="0.03" material="red" /><joint name="player1_RightHeel_joint" type="hinge" axis="1 0 0" limited="false" damping="0.5" /><geom type="capsule" fromto="0 0 0 -0.2568 0.0924 0.0144" size="0.0250" material="red" /><body name="player1_RightToe" pos="-0.2568 0.0924 0.0144"><geom type="sphere" size="0.025" material="red" /><joint name="player1_RightToe_joint" type="hinge" axis="1 0 0" limited="false" damping="0.5" /></body></body></body></body></body><geom type="capsule" fromto="0 0 0 -0.2616 -0.0588 0.4008" size="0.0500" material="red" /><body name="player1_Neck" pos="-0.2616 -0.0588 0.4008"><geom type="sphere" size="0.05" material="red" /><joint name="player1_Neck_joint" type="hinge" axis="1 0 0" limited="false" damping="0.5" /><geom type="capsule" fromto="0 0 0 -0.1644 -0.0120 0.1152" size="0.0500" material="red" /><body name="player1_Head" pos="-0.1644 -0.0120 0.1152"><geom type="sphere" size="0.11" material="red" /><joint name="player1_Head_joint" type="hinge" axis="1 0 0" limited="false" damping="0.5" /></body><geom type="capsule" fromto="0 0 0 0.0384 -0.1836 -0.0996" size="0.0500" material="red" /><body name="player1_LeftShoulder" pos="0.0384 -0.1836 -0.0996"><geom type="sphere" size="0.08" material="red" /><joint name="player1_LeftShoulder_joint" type="ball" limited="false" damping="0.5" /><geom type="capsule" fromto="0 0 0 -0.1836 -0.2184 -0.2052" size="0.0450" material="red" /><body name="player1_LeftElbow" pos="-0.1836 -0.2184 -0.2052"><geom type="sphere" size="0.045" material="red" /><joint name="player1_LeftElbow_joint" type="hinge" axis="0 1 0" limited="true" range="-2.3 0" damping="0.5" /><geom type="capsule" fromto="0 0 0 -0.2808 -0.0024 0.1404" size="0.0200" material="red" /><body name="player1_LeftWrist" pos="-0.2808 -0.0024 0.1404"><geom type="sphere" size="0.02" material="red" /><joint name="player1_LeftWrist_joint" type="hinge" axis="1 0 0" limited="false" damping="0.5" /><geom type="capsule" fromto="0 0 0 -0.0552 -0.0468 0.0660" size="0.0200" material="red" /><body name="player1_LeftHand" pos="-0.0552 -0.0468 0.0660"><geom type="sphere" size="0.02" material="red" /><joint name="player1_LeftHand_joint" type="hinge" axis="1 0 0" limited="false" damping="0.5" /><geom type="capsule" fromto="0 0 0 -0.0936 0.0228 0.0108" size="0.0200" material="red" /><body name="player1_LeftFingers" pos="-0.0936 0.0228 0.0108"><geom type="sphere" size="0.02" material="red" /><joint name="player1_LeftFingers_joint" type="hinge" axis="1 0 0" limited="false" damping="0.5" /></body></body></body></body></body><geom type="capsule" fromto="0 0 0 0.0312 0.2052 -0.0480" size="0.0500" material="red" /><body name="player1_RightShoulder" pos="0.0312 0.2052 -0.0480"><geom type="sphere" size="0.08" material="red" /><joint name="player1_RightShoulder_joint" type="ball" limited="false" damping="0.5" /><geom type="capsule" fromto="0 0 0 -0.2424 -0.0360 -0.2496" size="0.0450" material="red" /><body name="player1_RightElbow" pos="-0.2424 -0.0360 -0.2496"><geom type="sphere" size="0.045" material="red" /><joint name="player1_RightElbow_joint" type="hinge" axis="0 1 0" limited="true" range="-2.3 0" damping="0.5" /><geom type="capsule" fromto="0 0 0 -0.2604 -0.0744 0.1800" size="0.0200" material="red" /><body name="player1_RightWrist" pos="-0.2604 -0.0744 0.1800"><geom type="sphere" size="0.02" material="red" /><joint name="player1_RightWrist_joint" type="hinge" axis="1 0 0" limited="false" damping="0.5" /><geom type="capsule" fromto="0 0 0 -0.0720 -0.0180 0.0588" size="0.0200" material="red" /><body name="player1_RightHand" pos="-0.0720 -0.0180 0.0588"><geom type="sphere" size="0.02" material="red" /><joint name="player1_RightHand_joint" type="hinge" axis="1 0 0" limited="false" damping="0.5" /><geom type="capsule" fromto="0 0 0 -0.0864 -0.0324 -0.0204" size="0.0200" material="red" /><body name="player1_RightFingers" pos="-0.0864 -0.0324 -0.0204"><geom type="sphere" size="0.02" material="red" /><joint name="player1_RightFingers_joint" type="hinge" axis="1 0 0" limited="false" damping="0.5" /></body></body></body></body></body></body></body></worldbody><actuator><position name="player1_LeftHip_joint_act" joint="player1_LeftHip_joint" kp="50" /><position name="player1_LeftKnee_joint_act" joint="player1_LeftKnee_joint" kp="50" /><position name="player1_LeftAnkle_joint_act" joint="player1_LeftAnkle_joint" kp="50" /><position name="player1_LeftHeel_joint_act" joint="player1_LeftHeel_joint" kp="50" /><position name="player1_LeftToe_joint_act" joint="player1_LeftToe_joint" kp="50" /><position name="player1_RightHip_joint_act" joint="player1_RightHip_joint" kp="50" /><position name="player1_RightKnee_joint_act" joint="player1_RightKnee_joint" kp="50" /><position name="player1_RightAnkle_joint_act" joint="player1_RightAnkle_joint" kp="50" /><position name="player1_RightHeel_joint_act" joint="player1_RightHeel_joint" kp="50" /><position name="player1_RightToe_joint_act" joint="player1_RightToe_joint" kp="50" /><position name="player1_Neck_joint_act" joint="player1_Neck_joint" kp="50" /><position name="player1_Head_joint_act" joint="player1_Head_joint" kp="50" /><position name="player1_LeftShoulder_joint_act" joint="player1_LeftShoulder_joint" kp="50" /><position name="player1_LeftElbow_joint_act" joint="player1_LeftElbow_joint" kp="50" /><position name="player1_LeftWrist_joint_act" joint="player1_LeftWrist_joint" kp="50" /><position name="player1_LeftHand_joint_act" joint="player1_LeftHand_joint" kp="50" /><position name="player1_LeftFingers_joint_act" joint="player1_LeftFingers_joint" kp="50" /><position name="player1_RightShoulder_joint_act" joint="player1_RightShoulder_joint" kp="50" /><position name="player1_RightElbow_joint_act" joint="player1_RightElbow_joint" kp="50" /><position name="player1_RightWrist_joint_act" joint="player1_RightWrist_joint" kp="50" /><position name="player1_RightHand_joint_act" joint="player1_RightHand_joint" kp="50" /><position name="player1_RightFingers_joint_act" joint="player1_RightFingers_joint" kp="50" /></actuator></mujoco>