<?xml version='1.0' encoding='utf-8'?>
<mujoco model="bjj_player2"><compiler angle="radian" coordinate="local" /><default><joint armature="0.01" damping="0.1" limited="true" /><geom contype="1" conaffinity="1" friction="1 0.5 0.5" /></default><asset><material name="blue" rgba="0.2 0.2 0.8 1" /></asset><worldbody><geom name="floor" type="plane" pos="0 0 -0.6260" size="30 30 0.1" rgba="0.8 0.8 0.8 1" /><body name="player2_Core" pos="2.0880 -1.9512 -0.4716"><geom type="sphere" size="0.1" material="blue" /><freejoint name="player2_root" /><geom type="capsule" fromto="0 0 0 -0.3108 -0.0900 0.0240" size="0.0900" material="blue" /><body name="player2_LeftHip" pos="-0.3108 -0.0900 0.0240"><geom type="sphere" size="0.09" material="blue" /><joint name="player2_LeftHip_joint" type="ball" limited="false" damping="0.5" /><geom type="capsule" fromto="0 0 0 -0.3084 0.0648 0.4116" size="0.0500" material="blue" /><body name="player2_LeftKnee" pos="-0.3084 0.0648 0.4116"><geom type="sphere" size="0.05" material="blue" /><joint name="player2_LeftKnee_joint" type="hinge" axis="0 1 0" limited="true" range="-2.3 0" damping="0.5" /><geom type="capsule" fromto="0 0 0 -0.2472 0.0132 -0.4500" size="0.0300" material="blue" /><body name="player2_LeftAnkle" pos="-0.2472 0.0132 -0.4500"><geom type="sphere" size="0.03" material="blue" /><joint name="player2_LeftAnkle_joint" type="hinge" axis="1 0 0" limited="false" damping="0.5" /><geom type="capsule" fromto="0 0 0 0.0768 -0.0156 -0.0756" size="0.0300" material="blue" /><body name="player2_LeftHeel" pos="0.0768 -0.0156 -0.0756"><geom type="sphere" size="0.03" material="blue" /><joint name="player2_LeftHeel_joint" type="hinge" axis="1 0 0" limited="false" damping="0.5" /><geom type="capsule" fromto="0 0 0 -0.2724 0.0432 -0.0084" size="0.0250" material="blue" /><body name="player2_LeftToe" pos="-0.2724 0.0432 -0.0084"><geom type="sphere" size="0.025" material="blue" /><joint name="player2_LeftToe_joint" type="hinge" axis="1 0 0" limited="false" damping="0.5" /></body></body></body></body></body><geom type="capsule" fromto="0 0 0 -0.2616 0.1836 0.0312" size="0.0900" material="blue" /><body name="player2_RightHip" pos="-0.2616 0.1836 0.0312"><geom type="sphere" size="0.09" material="blue" /><joint name="player2_RightHip_joint" type="ball" limited="false" damping="0.5" /><geom type="capsule" fromto="0 0 0 0.1992 0.1308 0.4596" size="0.0500" material="blue" /><body name="player2_RightKnee" pos="0.1992 0.1308 0.4596"><geom type="sphere" size="0.05" material="blue" /><joint name="player2_RightKnee_joint" type="hinge" axis="0 1 0" limited="true" range="-2.3 0" damping="0.5" /><geom type="capsule" fromto="0 0 0 -0.4200 -0.2952 -0.0132" size="0.0300" material="blue" /><body name="player2_RightAnkle" pos="-0.4200 -0.2952 -0.0132"><geom type="sphere" size="0.03" material="blue" /><joint name="player2_RightAnkle_joint" type="hinge" axis="1 0 0" limited="false" damping="0.5" /><geom type="capsule" fromto="0 0 0 -0.0504 0.0576 -0.0720" size="0.0300" material="blue" /><body name="player2_RightHeel" pos="-0.0504 0.0576 -0.0720"><geom type="sphere" size="0.03" material="blue" /><joint name="player2_RightHeel_joint" type="hinge" axis="1 0 0" limited="false" damping="0.5" /><geom type="capsule" fromto="0 0 0 -0.0588 -0.2208 0.1536" size="0.0250" material="blue" /><body name="player2_RightToe" pos="-0.0588 -0.2208 0.1536"><geom type="sphere" size="0.025" material="blue" /><joint name="player2_RightToe_joint" type="hinge" axis="1 0 0" limited="false" damping="0.5" /></body></body></body></body></body><geom type="capsule" fromto="0 0 0 0.4716 -0.1200 -0.0036" size="0.0500" material="blue" /><body name="player2_Neck" pos="0.4716 -0.1200 -0.0036"><geom type="sphere" size="0.05" material="blue" /><joint name="player2_Neck_joint" type="hinge" axis="1 0 0" limited="false" damping="0.5" /><geom type="capsule" fromto="0 0 0 0.1596 -0.1200 0.0072" size="0.0500" material="blue" /><body name="player2_Head" pos="0.1596 -0.1200 0.0072"><geom type="sphere" size="0.11" material="blue" /><joint name="player2_Head_joint" type="hinge" axis="1 0 0" limited="false" damping="0.5" /></body><geom type="capsule" fromto="0 0 0 -0.1344 -0.1644 -0.0240" size="0.0500" material="blue" /><body name="player2_LeftShoulder" pos="-0.1344 -0.1644 -0.0240"><geom type="sphere" size="0.08" material="blue" /><joint name="player2_LeftShoulder_joint" type="ball" limited="false" damping="0.5" /><geom type="capsule" fromto="0 0 0 -0.3204 -0.1344 -0.0180" size="0.0450" material="blue" /><body name="player2_LeftElbow" pos="-0.3204 -0.1344 -0.0180"><geom type="sphere" size="0.045" material="blue" /><joint name="player2_LeftElbow_joint" type="hinge" axis="0 1 0" limited="true" range="-2.3 0" damping="0.5" /><geom type="capsule" fromto="0 0 0 0.2376 0.1440 0.1464" size="0.0200" material="blue" /><body name="player2_LeftWrist" pos="0.2376 0.1440 0.1464"><geom type="sphere" size="0.02" material="blue" /><joint name="player2_LeftWrist_joint" type="hinge" axis="1 0 0" limited="false" damping="0.5" /><geom type="capsule" fromto="0 0 0 0.0960 0.0048 -0.0036" size="0.0200" material="blue" /><body name="player2_LeftHand" pos="0.0960 0.0048 -0.0036"><geom type="sphere" size="0.02" material="blue" /><joint name="player2_LeftHand_joint" type="hinge" axis="1 0 0" limited="false" damping="0.5" /><geom type="capsule" fromto="0 0 0 0.0564 -0.0312 0.0708" size="0.0200" material="blue" /><body name="player2_LeftFingers" pos="0.0564 -0.0312 0.0708"><geom type="sphere" size="0.02" material="blue" /><joint name="player2_LeftFingers_joint" type="hinge" axis="1 0 0" limited="false" damping="0.5" /></body></body></body></body></body><geom type="capsule" fromto="0 0 0 -0.0324 0.2040 -0.0180" size="0.0500" material="blue" /><body name="player2_RightShoulder" pos="-0.0324 0.2040 -0.0180"><geom type="sphere" size="0.08" material="blue" /><joint name="player2_RightShoulder_joint" type="ball" limited="false" damping="0.5" /><geom type="capsule" fromto="0 0 0 0.0444 0.1848 0.2940" size="0.0450" material="blue" /><body name="player2_RightElbow" pos="0.0444 0.1848 0.2940"><geom type="sphere" size="0.045" material="blue" /><joint name="player2_RightElbow_joint" type="hinge" axis="0 1 0" limited="true" range="-2.3 0" damping="0.5" /><geom type="capsule" fromto="0 0 0 0.0948 -0.3048 -0.0396" size="0.0200" material="blue" /><body name="player2_RightWrist" pos="0.0948 -0.3048 -0.0396"><geom type="sphere" size="0.02" material="blue" /><joint name="player2_RightWrist_joint" type="hinge" axis="1 0 0" limited="false" damping="0.5" /><geom type="capsule" fromto="0 0 0 0.0144 -0.0408 0.0864" size="0.0200" material="blue" /><body name="player2_RightHand" pos="0.0144 -0.0408 0.0864"><geom type="sphere" size="0.02" material="blue" /><joint name="player2_RightHand_joint" type="hinge" axis="1 0 0" limited="false" damping="0.5" /><geom type="capsule" fromto="0 0 0 -0.0288 -0.0900 0.0168" size="0.0200" material="blue" /><body name="player2_RightFingers" pos="-0.0288 -0.0900 0.0168"><geom type="sphere" size="0.02" material="blue" /><joint name="player2_RightFingers_joint" type="hinge" axis="1 0 0" limited="false" damping="0.5" /></body></body></body></body></body></body></body></worldbody><actuator><position name="player2_LeftHip_joint_act" joint="player2_LeftHip_joint" kp="50" /><position name="player2_LeftKnee_joint_act" joint="player2_LeftKnee_joint" kp="50" /><position name="player2_LeftAnkle_joint_act" joint="player2_LeftAnkle_joint" kp="50" /><position name="player2_LeftHeel_joint_act" joint="player2_LeftHeel_joint" kp="50" /><position name="player2_LeftToe_joint_act" joint="player2_LeftToe_joint" kp="50" /><position name="player2_RightHip_joint_act" joint="player2_RightHip_joint" kp="50" /><position name="player2_RightKnee_joint_act" joint="player2_RightKnee_joint" kp="50" /><position name="player2_RightAnkle_joint_act" joint="player2_RightAnkle_joint" kp="50" /><position name="player2_RightHeel_joint_act" joint="player2_RightHeel_joint" kp="50" /><position name="player2_RightToe_joint_act" joint="player2_RightToe_joint" kp="50" /><position name="player2_Neck_joint_act" joint="player2_Neck_joint" kp="50" /><position name="player2_Head_joint_act" joint="player2_Head_joint" kp="50" /><position name="player2_LeftShoulder_joint_act" joint="player2_LeftShoulder_joint" kp="50" /><position name="player2_LeftElbow_joint_act" joint="player2_LeftElbow_joint" kp="50" /><position name="player2_LeftWrist_joint_act" joint="player2_LeftWrist_joint" kp="50" /><position name="player2_LeftHand_joint_act" joint="player2_LeftHand_joint" kp="50" /><position name="player2_LeftFingers_joint_act" joint="player2_LeftFingers_joint" kp="50" /><position name="player2_RightShoulder_joint_act" joint="player2_RightShoulder_joint" kp="50" /><position name="player2_RightElbow_joint_act" joint="player2_RightElbow_joint" kp="50" /><position name="player2_RightWrist_joint_act" joint="player2_RightWrist_joint" kp="50" /><position name="player2_RightHand_joint_act" joint="player2_RightHand_joint" kp="50" /><position name="player2_RightFingers_joint_act" joint="player2_RightFingers_joint" kp="50" /></actuator></mujoco>